<?xml version="1.0" encoding="utf-8"?>
<!-- =================================================================================== -->
<!-- |    This document was autogenerated by xacro from irb2600_12_165.xacro           | -->
<!-- |    EDITING THIS FILE BY HAND IS NOT RECOMMENDED                                 | -->
<!-- =================================================================================== -->
<robot name="abb_irb2600_12_165">
  <!-- Conversion were obtained from http://www.e-paint.co.uk/Lab_values.asp
       unless otherwise stated. -->
  <!-- links -->
  <link name="base_link">
    <visual>
      <origin rpy="0 0 0" xyz="0 0 0"/>
      <geometry>
        <mesh filename="package://abb_irb2600_support/meshes/irb2600_12_165/visual/base_link.stl"/>
      </geometry>
      <material name="">
        <color rgba="0.7372549 0.3490196 0.1607843 1"/>
      </material>
    </visual>
    <collision>
      <origin rpy="0 0 0" xyz="0 0 0"/>
      <geometry>
        <mesh filename="package://abb_irb2600_support/meshes/irb2600_12_165/collision/base_link.stl"/>
      </geometry>
    </collision>
    <inertial>
      <mass value="92.5052"/>
      <origin xyz="-0.0930 0.0004 0.0959"/>
      <inertia ixx="1.2218" ixy="-0.0110" ixz="-0.0666" iyy="2.5212" iyz="-0.0008" izz="3.1801"/>
    </inertial>
  </link>
  <link name="link_1">
    <visual>
      <origin rpy="0 0 0" xyz="0 0 0"/>
      <geometry>
        <mesh filename="package://abb_irb2600_support/meshes/irb2600_12_165/visual/link_1.stl"/>
      </geometry>
      <material name="">
        <color rgba="0.7372549 0.3490196 0.1607843 1"/>
      </material>
    </visual>
    <collision>
      <origin rpy="0 0 0" xyz="0 0 0"/>
      <geometry>
        <mesh filename="package://abb_irb2600_support/meshes/irb2600_12_165/collision/link_1.stl"/>
      </geometry>
    </collision>
    <inertial>
      <mass value="69.3794"/>
      <origin xyz="0.0431 0.0070 0.3897"/>
      <inertia ixx="1.1465" ixy="0.0280" ixz="0.1205" iyy="1.7541" iyz="0.0173" izz="1.6616"/>
    </inertial>
  </link>
  <link name="link_2">
    <visual>
      <origin rpy="0 0 0" xyz="0 0 0"/>
      <geometry>
        <mesh filename="package://abb_irb2600_support/meshes/irb2600_12_165/visual/link_2.stl"/>
      </geometry>
      <material name="">
        <color rgba="0.7372549 0.3490196 0.1607843 1"/>
      </material>
    </visual>
    <collision>
      <origin rpy="0 0 0" xyz="0 0 0"/>
      <geometry>
        <mesh filename="package://abb_irb2600_support/meshes/irb2600_12_165/collision/link_2.stl"/>
      </geometry>
    </collision>
    <inertial>
      <mass value="35.0020"/>
      <origin xyz="0.1501 -0.1725 0.7659"/>
      <inertia ixx="1.5756" ixy="0.0000" ixz="-0.0005" iyy="1.6204" iyz="-0.0093" izz="0.1065"/>
    </inertial>
  </link>
  <link name="link_3">
    <visual>
      <origin rpy="0 0 0" xyz="0 0 0"/>
      <geometry>
        <mesh filename="package://abb_irb2600_support/meshes/irb2600_12_165/visual/link_3.stl"/>
      </geometry>
      <material name="">
        <color rgba="0.7372549 0.3490196 0.1607843 1"/>
      </material>
    </visual>
    <collision>
      <origin rpy="0 0 0" xyz="0 0 0"/>
      <geometry>
        <mesh filename="package://abb_irb2600_support/meshes/irb2600_12_165/collision/link_3.stl"/>
      </geometry>
    </collision>
    <inertial>
      <mass value="68.5583"/>
      <origin xyz="0.1933 0.0140 1.2203"/>
      <inertia ixx="0.8500" ixy="-0.0228" ixz="0.0536" iyy="1.1656" iyz="-0.0282" izz="1.0043"/>
    </inertial>
  </link>
  <link name="link_4">
    <visual>
      <origin rpy="0 0 0" xyz="0 0 0"/>
      <geometry>
        <mesh filename="package://abb_irb2600_support/meshes/irb2600_12_165/visual/link_4.stl"/>
      </geometry>
      <material name="">
        <color rgba="0.7372549 0.3490196 0.1607843 1"/>
      </material>
    </visual>
    <collision>
      <origin rpy="0 0 0" xyz="0 0 0"/>
      <geometry>
        <mesh filename="package://abb_irb2600_support/meshes/irb2600_12_165/collision/link_4.stl"/>
      </geometry>
    </collision>
    <inertial>
      <mass value="18.0455"/>
      <origin xyz="0.7503 0.0012 1.2603"/>
      <inertia ixx="0.0434" ixy="0.0043" ixz="0.0005" iyy="0.5171" iyz="0.0000" izz="0.5274"/>
    </inertial>
  </link>
  <link name="link_5">
    <visual>
      <origin rpy="0 0 0" xyz="0 0 0"/>
      <geometry>
        <mesh filename="package://abb_irb2600_support/meshes/irb2600_12_165/visual/link_5.stl"/>
      </geometry>
      <material name="">
        <color rgba="0.7372549 0.3490196 0.1607843 1"/>
      </material>
    </visual>
    <collision>
      <origin rpy="0 0 0" xyz="0 0 0"/>
      <geometry>
        <mesh filename="package://abb_irb2600_support/meshes/irb2600_12_165/collision/link_5.stl"/>
      </geometry>
    </collision>
    <inertial>
      <mass value="1.0738"/>
      <origin xyz="0.9452 0.0000 1.2609"/>
      <inertia ixx="0.0009" ixy="0.0000" ixz="0.0000" iyy="0.0016" iyz="0.0000" izz="0.0010"/>
    </inertial>
  </link>
  <link name="link_6">
    <visual>
      <origin rpy="0 0 0" xyz="0 0 0"/>
      <geometry>
        <mesh filename="package://abb_irb2600_support/meshes/irb2600_12_165/visual/link_6.stl"/>
      </geometry>
      <material name="">
        <color rgba="0.5 0.5 0.5 1"/>
      </material>
    </visual>
    <collision>
      <origin rpy="0 0 0" xyz="0 0 0"/>
      <geometry>
        <mesh filename="package://abb_irb2600_support/meshes/irb2600_12_165/collision/link_6.stl"/>
      </geometry>
    </collision>
    <inertial>
      <mass value="0.1418"/>
      <origin xyz="1.0173 0.0000 1.2598"/>
      <inertia ixx="0.0001" ixy="0.0000" ixz="0.0000" iyy="0.0000" iyz="0.0000" izz="0.0000"/>
    </inertial>
  </link>
  <!-- Joints -->
  <joint name="joint_1" type="revolute">
    <origin rpy="0 0 0" xyz="0 0 0.445"/>
    <parent link="base_link"/>
    <child link="link_1"/>
    <axis xyz="0 0 1"/>
    <limit effort="0" lower="-3.14159" upper="3.14159" velocity="3.054"/>
  </joint>
  <joint name="joint_2" type="revolute">
    <origin rpy="0 0 0" xyz="0.15 0 0.0"/>
    <parent link="link_1"/>
    <child link="link_2"/>
    <axis xyz="0 1 0"/>
    <limit effort="0" lower="-2.705" upper="1.658" velocity="3.054"/>
  </joint>
  <joint name="joint_3" type="revolute">
    <origin rpy="0 0 0" xyz="0 0 0.7"/>
    <parent link="link_2"/>
    <child link="link_3"/>
    <axis xyz="0 1 0"/>
    <limit effort="0" lower="-2.705" upper="1.309" velocity="3.054"/>
  </joint>
  <joint name="joint_4" type="revolute">
    <origin rpy="0 0 0" xyz="0 0 0.115"/>
    <parent link="link_3"/>
    <child link="link_4"/>
    <axis xyz="1 0 0"/>
    <limit effort="0" lower="-6.981" upper="6.981" velocity="6.283"/>
  </joint>
  <joint name="joint_5" type="revolute">
    <origin rpy="0 0 0" xyz="0.795 0 0 "/>
    <parent link="link_4"/>
    <child link="link_5"/>
    <axis xyz="0 1 0"/>
    <limit effort="0" lower="-2.094" upper="2.094" velocity="6.283"/>
  </joint>
  <joint name="joint_6" type="revolute">
    <origin rpy="0 0 0" xyz="0.085 0 0"/>
    <parent link="link_5"/>
    <child link="link_6"/>
    <axis xyz="1 0 0"/>
    <limit effort="0" lower="-6.981" upper="6.981" velocity="8.727"/>
  </joint>
  <!-- ROS-Industrial 'base' frame: base_link to ABB World Coordinates transform -->
  <link name="base"/>
  <joint name="base_link-base" type="fixed">
    <origin rpy="0 0 0" xyz="0 0 0"/>
    <parent link="base_link"/>
    <child link="base"/>
  </joint>
  <!-- ROS-Industrial 'flange' frame: attachment point for EEF models -->
  <link name="flange"/>
  <joint name="joint_6-flange" type="fixed">
    <origin rpy="0 0 0" xyz="0 0 0"/>
    <parent link="link_6"/>
    <child link="flange"/>
  </joint>
  <!-- ROS-Industrial 'tool0' frame: all-zeros tool frame -->
  <link name="tool0"/>
  <joint name="link_6-tool0" type="fixed">
    <origin rpy="0 1.57079632679 0" xyz="0 0 0"/>
    <parent link="flange"/>
    <child link="tool0"/>
  </joint>
</robot>

